Workbook

Sheet PG DAILY DATA
A1: Date | B1: Open | C1: High | D1: Low | E1: Close | F1: Adj Close | G1: Daily Returns | I1: (2) Plot returns as a function of time. Is there a significant linear or non-linear trend?
A2: 45607 | B2: 167 | C2: 168.52 | D2: 165.78 | E2: 166.03 | F2: 166.03 | G2: =(F2-F3)/F3 -> -0.010017292
A3: 45604 | B3: 164.02 | C3: 167.75 | D3: 163.93 | E3: 167.71 | F3: 167.71 | G3: =(F3-F4)/F4 -> 0.026314179
A4: 45603 | B4: 161.96 | C4: 163.95 | D4: 161.48 | E4: 163.41 | F4: 163.41 | G4: =(F4-F5)/F5 -> 0.014653834 | I4: The R² of the linear trend line is very low (~0.04%) --> NO significant linear trend.
A5: 45602 | B5: 165.61 | C5: 166.04 | D5: 159.81 | E5: 161.05 | F5: 161.05 | G5: =(F5-F6)/F6 -> -0.028414575 | I5: Returns fluctuate randomly around zero --> consistent with weak-form market efficiency.
A6: 45601 | B6: 164.33 | C6: 166.32 | D6: 164.33 | E6: 165.76 | F6: 165.76 | G6: =(F6-F7)/F7 -> 0.0041192149
A7: 45600 | B7: 165.72 | C7: 166.27 | D7: 164.58 | E7: 165.08 | F7: 165.08 | G7: =(F7-F8)/F8 -> -0.0001211387 | I7: FORMULA: DAILY RETURNS = (Adj Close[t] - Adj Close[t-1]) / Adj Close[t-1]
A8: 45597 | B8: 165.31 | C8: 166.35 | D8: 164.99 | E8: 165.1 | F8: 165.1 | G8: =(F8-F9)/F9 -> -0.00048432014 | I8: In Excel (newest first): =(F2-F3)/F3
A9: 45596 | B9: 165.76 | C9: 167.04 | D9: 165.09 | E9: 165.18 | F9: 165.18 | G9: =(F9-F10)/F10 -> -0.0058979297
A10: 45595 | B10: 167.09 | C10: 167.32 | D10: 165.96 | E10: 166.16 | F10: 166.16 | G10: =(F10-F11)/F11 -> -0.0060417539
A11: 45594 | B11: 168.86 | C11: 168.86 | D11: 166.83 | E11: 167.17 | F11: 167.17 | G11: =(F11-F12)/F12 -> -0.012581217
A12: 45593 | B12: 169.28 | C12: 169.66 | D12: 168.38 | E12: 169.3 | F12: 169.3 | G12: =(F12-F13)/F13 -> 0.0064201641
A13: 45590 | B13: 168.92 | C13: 169.4 | D13: 168.04 | E13: 168.22 | F13: 168.22 | G13: =(F13-F14)/F14 -> -0.0082537437
A14: 45589 | B14: 169.42 | C14: 169.96 | D14: 168.93 | E14: 169.62 | F14: 169.62 | G14: =(F14-F15)/F15 -> 0.00023587687
A15: 45588 | B15: 169.55 | C15: 170.17 | D15: 168.73 | E15: 169.58 | F15: 169.58 | G15: =(F15-F16)/F16 -> -0.00070713023
A16: 45587 | B16: 168.57 | C16: 170.73 | D16: 168.57 | E16: 169.7 | F16: 169.7 | G16: =(F16-F17)/F17 -> 0.00094373009
A17: 45586 | B17: 170.98 | C17: 171.48 | D17: 168.45 | E17: 169.54 | F17: 169.54 | G17: =(F17-F18)/F18 -> -0.010158804
A18: 45583 | B18: 170.3 | C18: 172.21 | D18: 168.46 | E18: 171.28 | F18: 171.28 | G18: =(F18-F19)/F19 -> -0.0058045043
A19: 45582 | B19: 172.18 | C19: 173.68 | D19: 171.76 | E19: 172.28 | F19: 172.28 | G19: =(F19-F20)/F20 -> -0.0005801137
A20: 45581 | B20: 171.88 | C20: 172.59 | D20: 170.89 | E20: 172.38 | F20: 172.38 | G20: =(F20-F21)/F21 -> -0.0068560235
... A506: 44873 | B506: 136.82 | C506: 137.52 | D506: 135.8 | E506: 136.81 | F506: 136.81 | G506: =(F506-F507)/F507 -> 0.0022710623
A507: 44872 | B507: 135.35 | C507: 137.19 | D507: 135.06 | E507: 136.5 | F507: 136.5

Sheet PG MONTHLY DATA
A1: Date | B1: Open | C1: High | D1: Low | E1: Close | F1: Adj Close | G1: Monthly Return | H1: MKT-RF | I1: RF (%) | J1: RF (decimals) | K1: EXCESS RETURNS | M1: (3) Average & Std Dev_PG vs Mkt-RF (Risk-Return Trade-off) | T1: MKT-RF (%) | U1: RF (%) | V1: SMB (%) | W1: HML (%)
A2: 45596 | B2: 173.24 | C2: 174.91 | D2: 165.09 | E2: 165.18 | F2: 165.18 | G2: =(F2-F3)/F3 -> -0.04630485 | H2: =T2/100 -> -0.01 | I2: =U2 -> 0.39 | J2: =U2/100 -> 0.0039 | K2: =G2-J2 -> -0.05020485 | T2: -1 | U2: 0.39 | V2: -0.99 | W2: 0.86
A3: 45565 | B3: 171.03 | C3: 177.94 | D3: 170.38 | E3: 173.2 | F3: 173.2 | G3: =(F3-F4)/F4 -> 0.0096770433 | H3: =T3/100 -> 0.0172 | I3: =U3 -> 0.4 | J3: =U3/100 -> 0.004 | K3: =G3-J3 -> 0.0056770433 | M3: PG EXCESS RETURNS | T3: 1.72 | U3: 0.4 | V3: -0.13 | W3: -2.76
A4: 45535 | B4: 160.88 | C4: 171.89 | D4: 160.68 | E4: 171.54 | F4: 171.54 | G4: =(F4-F5)/F5 -> 0.067056482 | H4: =T4/100 -> 0.016 | I4: =U4 -> 0.48 | J4: =U4/100 -> 0.0048 | K4: =G4-J4 -> 0.062256482 | M4: AVERAGE | N4: =AVERAGE(K2:K145) -> 0.0059196043 | O4: ← Performance of the stock | T4: 1.6 | U4: 0.48 | V4: -3.49 | W4: -1.1
A5: 45504 | B5: 165.59 | C5: 170.92 | D5: 158.04 | E5: 160.76 | F5: 160.76 | G5: =(F5-F6)/F6 -> -0.025224351 | H5: =T5/100 -> 0.0122 | I5: =U5 -> 0.45 | J5: =U5/100 -> 0.0045 | K5: =G5-J5 -> -0.029724351 | M5: STD DEVIATION | N5: =STDEV(K2:K145) -> 0.04435982 | O5: ← Risk of the stock | T5: 1.22 | U5: 0.45 | V5: 6.81 | W5: 5.62
A6: 45473 | B6: 163.93 | C6: 169.41 | D6: 163.63 | E6: 164.92 | F6: 164.92 | G6: =(F6-F7)/F7 -> 0.0023094688 | H6: =T6/100 -> 0.028 | I6: =U6 -> 0.41 | J6: =U6/100 -> 0.0041 | K6: =G6-J6 -> -0.0017905312 | T6: 2.8 | U6: 0.41 | V6: -3 | W6: -3.36
A7: 45443 | B7: 163.28 | C7: 168.54 | D7: 161.42 | E7: 164.54 | F7: 164.54 | G7: =(F7-F8)/F8 -> 0.0082107843 | H7: =T7/100 -> 0.0433 | I7: =U7 -> 0.44 | J7: =U7/100 -> 0.0044 | K7: =G7-J7 -> 0.0038107843 | M7: MKT-RF | T7: 4.33 | U7: 0.44 | V7: 0.55 | W7: -1.31
A8: 45412 | B8: 161.78 | C8: 164.32 | D8: 153.52 | E8: 163.2 | F8: 163.2 | G8: =(F8-F9)/F9 -> 0.0058551618 | H8: =T8/100 -> -0.0465 | I8: =U8 -> 0.47 | J8: =U8/100 -> 0.0047 | K8: =G8-J8 -> 0.0011551618 | M8: AVERAGE | N8: =AVERAGE(H2:H145) -> 0.011027083 | O8: ← Market performance | T8: -4.65 | U8: 0.47 | V8: -2.37 | W8: -0.45
A9: 45382 | B9: 158.05 | C9: 163.14 | D9: 157.61 | E9: 162.25 | F9: 162.25 | G9: =(F9-F10)/F10 -> 0.020825469 | H9: =T9/100 -> 0.0284 | I9: =U9 -> 0.43 | J9: =U9/100 -> 0.0043 | K9: =G9-J9 -> 0.016525469 | M9: STD DEVIATION | N9: =STDEV(H2:H145) -> 0.042884405 | O9: ← Market risk | T9: 2.84 | U9: 0.43 | V9: -2.5 | W9: 4.16
A10: 45351 | B10: 156.77 | C10: 161.74 | D10: 154.91 | E10: 158.94 | F10: 158.94 | G10: =(F10-F11)/F11 -> 0.011454754 | H10: =T10/100 -> 0.0507 | I10: =U10 -> 0.42 | J10: =U10/100 -> 0.0042 | K10: =G10-J10 -> 0.0072547537 | T10: 5.07 | U10: 0.42 | V10: -0.24 | W10: -3.43
A11: 45322 | B11: 146.36 | C11: 158.5 | D11: 146.28 | E11: 157.14 | F11: 157.14 | G11: =(F11-F12)/F12 -> 0.072335199 | H11: =T11/100 -> 0.0073 | I11: =U11 -> 0.47 | J11: =U11/100 -> 0.0047 | K11: =G11-J11 -> 0.067635199 | M11: Discussion: | T11: 0.73 | U11: 0.47 | V11: -5.07 | W11: -2.38
A12: 45291 | B12: 153.33 | C12: 153.49 | D12: 142.5 | E12: 146.54 | F12: 146.54 | G12: =(F12-F13)/F13 -> -0.045466389 | H12: =T12/100 -> 0.0485 | I12: =U12 -> 0.43 | J12: =U12/100 -> 0.0043 | K12: =G12-J12 -> -0.049766389 | M12: PG avg excess return = | N12: =AVERAGE(K2:K145) -> 0.0059196043 | O12: vs Mkt-RF avg: | P12: =AVERAGE(H2:H145) -> 0.011027083 | T12: 4.85 | U12: 0.43 | V12: 6.3 | W12: 4.89
A13: 45260 | B13: 150.68 | C13: 153.63 | D13: 148.83 | E13: 153.52 | F13: 153.52 | G13: =(F13-F14)/F14 -> 0.023262014 | H13: =T13/100 -> 0.0888 | I13: =U13 -> 0.44 | J13: =U13/100 -> 0.0044 | K13: =G13-J13 -> 0.018862014 | M13: PG underperformed market on avg, with comparable risk --> less favorable risk-return trade-off. | T13: 8.88 | U13: 0.44 | V13: -0.1 | W13: 1.67
A14: 45230 | B14: 144.78 | C14: 151.38 | D14: 141.45 | E14: 150.03 | F14: 150.03 | G14: =(F14-F15)/F15 -> 0.028589058 | H14: =T14/100 -> -0.0315 | I14: =U14 -> 0.47 | J14: =U14/100 -> 0.0047 | K14: =G14-J14 -> 0.023889058 | T14: -3.15 | U14: 0.47 | V14: -3.86 | W14: 0.2
A15: 45199 | B15: 154.9 | C15: 155.32 | D15: 144.82 | E15: 145.86 | F15: 145.86 | G15: =(F15-F16)/F16 -> -0.054943631 | H15: =T15/100 -> -0.0523 | I15: =U15 -> 0.43 | J15: =U15/100 -> 0.0043 | K15: =G15-J15 -> -0.059243631 | M15: (4) Correlation_PG Excess Returns vs Mkt-RF | T15: -5.23 | U15: 0.43 | V15: -2.51 | W15: 1.49
A16: 45169 | B16: 155.88 | C16: 158.38 | D16: 150.93 | E16: 154.34 | F16: 154.34 | G16: =(F16-F17)/F17 -> -0.012539987 | H16: =T16/100 -> -0.0236 | I16: =U16 -> 0.45 | J16: =U16/100 -> 0.0045 | K16: =G16-J16 -> -0.017039987 | M16: Correlation = | N16: =CORREL(K2:K145,H2:H145) -> 0.36405514 | O16: Positive but moderate (~0.36) --> PG moves with market, not a pure tracker. | T16: -2.36 | U16: 0.45 | V16: -3.14 | W16: -1.15
A17: 45138 | B17: 151.48 | C17: 157.68 | D17: 146.96 | E17: 156.3 | F17: 156.3 | G17: =(F17-F18)/F18 -> 0.030051404 | H17: =T17/100 -> 0.0321 | I17: =U17 -> 0.45 | J17: =U17/100 -> 0.0045 | K17: =G17-J17 -> 0.025551404 | T17: 3.21 | U17: 0.45 | V17: 2.05 | W17: 4.06
A18: 45107 | B18: 143.25 | C18: 152.07 | D18: 142.45 | E18: 151.74 | F18: 151.74 | G18: =(F18-F19)/F19 -> 0.064842105 | H18: =T18/100 -> 0.0646 | I18: =U18 -> 0.4 | J18: =U18/100 -> 0.004 | K18: =G18-J18 -> 0.060842105 | M18: (5) OLS Estimators_CAPM: R_PG = α + β·(Mkt-RF) + ε | T18: 6.46 | U18: 0.4 | V18: 1.49 | W18: -0.13
A19: 45077 | B19: 156.03 | C19: 157.57 | D19: 141.9 | E19: 142.5 | F19: 142.5 | G19: =(F19-F20)/F20 -> -0.088758153 | H19: =T19/100 -> 0.0034 | I19: =U19 -> 0.36 | J19: =U19/100 -> 0.0036 | K19: =G19-J19 -> -0.092358153 | M19: α (Intercept) = | N19: ='CAPM Regression Output'!B16 -> 0.0017670224 | O19: Avg monthly excess return unexplained by market --> positive but not significant | T19: 0.34 | U19: 0.36 | V19: 1.6 | W19: -7.79
A20: 45046 | B20: 148.43 | C20: 158.11 | D20: 147.09 | E20: 156.38 | F20: 156.38 | G20: =(F20-F21)/F21 -> 0.05171834 | H20: =T20/100 -> 0.0062 | I20: =U20 -> 0.35 | J20: =U20/100 -> 0.0035 | K20: =G20-J20 -> 0.04821834 | M20: β (Slope) = | N20: ='CAPM Regression Output'!B17 -> 0.37658026 | O20: PG moves β% per 1% move in Mkt-RF | T20: 0.62 | U20: 0.35 | V20: -3.37 | W20: -0.12
A21: 45016 | B21: 138.05 | C21: 148.69 | D21: 136.1 | E21: 148.69 | F21: 148.69 | G21: =(F21-F22)/F22 -> 0.080910148 | H21: =T21/100 -> 0.0248 | I21: =U21 -> 0.36 | J21: =U21/100 -> 0.0036 | K21: =G21-J21 -> 0.077310148 | M21: → See CAPM Regression Output sheet for full results. | T21: 2.48 | U21: 0.36 | V21: -5.48 | W21: -9.05
A22: 44985 | B22: 142.08 | C22: 144.1 | D22: 135.83 | E22: 137.56 | F22: 137.56 | G22: =(F22-F23)/F23 -> -0.033853069 | H22: =T22/100 -> -0.0257 | I22: =U22 -> 0.34 | J22: =U22/100 -> 0.0034 | K22: =G22-J22 -> -0.037253069 | T22: -2.57 | U22: 0.34 | V22: 1.05 | W22: -0.8
A23: 44957 | B23: 150.95 | C23: 154.8 | D23: 138.73 | E23: 142.38 | F23: 142.38 | G23: =(F23-F24)/F24 -> -0.060570071 | H23: =T23/100 -> 0.0661 | I23: =U23 -> 0.35 | J23: =U23/100 -> 0.0035 | K23: =G23-J23 -> -0.064070071 | M23: (6) H₀: β=0 vs H₁: β≠0 (5% two-tailed) | T23: 6.61 | U23: 0.35 | V23: 5.01 | W23: -3.94
A24: 44926 | B24: 149.53 | C24: 154.65 | D24: 148.08 | E24: 151.56 | F24: 151.56 | G24: =(F24-F25)/F25 -> 0.016090105 | H24: =T24/100 -> -0.0638 | I24: =U24 -> 0.33 | J24: =U24/100 -> 0.0033 | K24: =G24-J24 -> 0.012790105 | M24: t-stat = | N24: ='CAPM Regression Output'!D17 -> 4.6578516 | O24: t-critical (5%, 2-tail) = | P24: =_xlfn.T.INV.2T(0.05,142) -> 1.976811 | T24: -6.38 | U24: 0.33 | V24: -0.76 | W24: 1.34
A25: 44895 | B25: 134.7 | C25: 149.16 | D25: 130.96 | E25: 149.16 | F25: 149.16 | G25: =(F25-F26)/F26 -> 0.10759635 | H25: =T25/100 -> 0.0465 | I25: =U25 -> 0.29 | J25: =U25/100 -> 0.0029 | K25: =G25-J25 -> 0.10469635 | M25: p-value = | N25: ='CAPM Regression Output'!E17 -> 7.2745792e-06 | O25: → p < 0.05: REJECT H₀ --> β is significant at 5% | T25: 4.65 | U25: 0.29 | V25: -3.57 | W25: 1.48
A26: 44865 | B26: 127.25 | C26: 135.67 | D26: 122.18 | E26: 134.67 | F26: 134.67 | G26: =(F26-F27)/F27 -> 0.066693069 | H26: =T26/100 -> 0.0785 | I26: =U26 -> 0.23 | J26: =U26/100 -> 0.0023 | K26: =G26-J26 -> 0.064393069 | M26: Market risk significantly explains PG returns. | T26: 7.85 | U26: 0.23 | V26: 0.01 | W26: 7.97
A27: 44834 | B27: 137.83 | C27: 141.8 | D27: 126.21 | E27: 126.25 | F27: 126.25 | G27: =(F27-F28)/F28 -> -0.084746991 | H27: =T27/100 -> -0.0934 | I27: =U27 -> 0.19 | J27: =U27/100 -> 0.0019 | K27: =G27-J27 -> -0.086646991 | T27: -9.34 | U27: 0.19 | V27: -0.76 | W27: 0.03
A28: 44804 | B28: 138.34 | C28: 150.63 | D28: 137.86 | E28: 137.94 | F28: 137.94 | G28: =(F28-F29)/F29 -> -0.0069829386 | H28: =T28/100 -> -0.0377 | I28: =U28 -> 0.19 | J28: =U28/100 -> 0.0019 | K28: =G28-J28 -> -0.0088829386 | M28: (7) H₀: β≤1 vs H₁: β>1 (1% one-tailed) | T28: -3.77 | U28: 0.19 | V28: 1.41 | W28: 0.18
A29: 44773 | B29: 144.24 | C29: 148.61 | D29: 138.23 | E29: 138.91 | F29: 138.91 | G29: =(F29-F30)/F30 -> -0.033938382 | H29: =T29/100 -> 0.0957 | I29: =U29 -> 0.08 | J29: =U29/100 -> 0.0008 | K29: =G29-J29 -> -0.034738382 | M29: t-stat = (β−1)/se = | N29: =('CAPM Regression Output'!B17-1)/'CAPM Regression Output'!C17 -> -7.7109635 | O29: t-critical (1%, 1-tail) = | P29: =_xlfn.T.INV(0.99,142) -> 2.352895 | T29: 9.57 | U29: 0.08 | V29: 2.84 | W29: -4.15
A30: 44742 | B30: 148 | C30: 148.12 | D30: 129.5 | E30: 143.79 | F30: 143.79 | G30: =(F30-F31)/F31 -> -0.02765756 | H30: =T30/100 -> -0.084 | I30: =U30 -> 0.06 | J30: =U30/100 -> 0.0006 | K30: =G30-J30 -> -0.02825756 | M30: t-stat < t-critical → FAIL TO REJECT H₀ | T30: -8.4 | U30: 0.06 | V30: 2.07 | W30: -6
A31: 44712 | B31: 161.6 | C31: 162 | D31: 139.18 | E31: 147.88 | F31: 147.88 | G31: =(F31-F32)/F32 -> -0.078916225 | H31: =T31/100 -> -0.0034 | I31: =U31 -> 0.03 | J31: =U31/100 -> 0.0003 | K31: =G31-J31 -> -0.079216225 | M31: PG is a DEFENSIVE stock (β<1) --> less risky than the overall market. | T31: -0.34 | U31: 0.03 | V31: -1.84 | W31: 8.44
A32: 44681 | B32: 153.52 | C32: 164.9 | D32: 151.26 | E32: 160.55 | F32: 160.55 | G32: =(F32-F33)/F33 -> 0.050719895 | H32: =T32/100 -> -0.0941 | I32: =U32 -> 0 | J32: =U32/100 -> 0 | K32: =G32-J32 -> 0.050719895 | T32: -9.41 | U32: 0 | V32: -1.35 | W32: 6.18
A33: 44651 | B33: 154.31 | C33: 156.47 | D33: 143.03 | E33: 152.8 | F33: 152.8 | G33: =(F33-F34)/F34 -> -0.019821669 | H33: =T33/100 -> 0.0308 | I33: =U33 -> 0 | J33: =U33/100 -> 0 | K33: =G33-J33 -> -0.019821669 | T33: 3.08 | U33: 0 | V33: -1.55 | W33: -1.9
A34: 44620 | B34: 160.79 | C34: 164.98 | D34: 150.56 | E34: 155.89 | F34: 155.89 | G34: =(F34-F35)/F35 -> -0.028420069 | H34: =T34/100 -> -0.0228 | I34: =U34 -> 0 | J34: =U34/100 -> 0 | K34: =G34-J34 -> -0.028420069 | T34: -2.28 | U34: 0 | V34: 2.16 | W34: 3.06
A35: 44592 | B35: 161.69 | C35: 165.35 | D35: 156.04 | E35: 160.45 | F35: 160.45 | G35: =(F35-F36)/F36 -> -0.019134369 | H35: =T35/100 -> -0.0616 | I35: =U35 -> 0 | J35: =U35/100 -> 0 | K35: =G35-J35 -> -0.019134369 | T35: -6.16 | U35: 0 | V35: -5.93 | W35: 12.86
A36: 44561 | B36: 144.85 | C36: 164.98 | D36: 144.85 | E36: 163.58 | F36: 163.58 | G36: =(F36-F37)/F37 -> 0.13141513 | H36: =T36/100 -> 0.0323 | I36: =U36 -> 0.01 | J36: =U36/100 -> 0.0001 | K36: =G36-J36 -> 0.13131513 | T36: 3.23 | U36: 0.01 | V36: -1.63 | W36: 3.25
A37: 44530 | B37: 143.36 | C37: 149.72 | D37: 142.28 | E37: 144.58 | F37: 144.58 | G37: =(F37-F38)/F38 -> 0.011119659 | H37: =T37/100 -> -0.0158 | I37: =U37 -> 0 | J37: =U37/100 -> 0 | K37: =G37-J37 -> 0.011119659 | T37: -1.58 | U37: 0 | V37: -1.31 | W37: -0.37
A38: 44500 | B38: 139.93 | C38: 144.87 | D38: 137.6 | E38: 142.99 | F38: 142.99 | G38: =(F38-F39)/F39 -> 0.022818312 | H38: =T38/100 -> 0.0663 | I38: =U38 -> 0 | J38: =U38/100 -> 0 | K38: =G38-J38 -> 0.022818312 | T38: 6.63 | U38: 0 | V38: -2.26 | W38: -0.53
A39: 44469 | B39: 142.33 | C39: 147.23 | D39: 139.53 | E39: 139.8 | F39: 139.8 | G39: =(F39-F40)/F40 -> -0.01818948 | H39: =T39/100 -> -0.044 | I39: =U39 -> 0 | J39: =U39/100 -> 0 | K39: =G39-J39 -> -0.01818948 | T39: -4.4 | U39: 0 | V39: 0.66 | W39: 5.12
A40: 44439 | B40: 141.77 | C40: 145.98 | D40: 140.8 | E40: 142.39 | F40: 142.39 | G40: =(F40-F41)/F41 -> 0.0011249385 | H40: =T40/100 -> 0.0294 | I40: =U40 -> 0 | J40: =U40/100 -> 0 | K40: =G40-J40 -> 0.0011249385 | T40: 2.94 | U40: 0 | V40: -0.32 | W40: -0.23
...

Sheet QUESTIONS 8-10
A1: Date | B1: EXCESS RETURNS | C1: MKT-RF | D1: RF % | E1: RF (decimals) | F1: SMB (%) | G1: SMB (decimals) | H1: HML (%) | I1: HML (decimals) | K1: (8) Correlation MKT/SMB/HML_Collinearity Check
A2: ='PG MONTHLY DATA'!A2 -> 45596 | B2: ='PG MONTHLY DATA'!K2 -> -0.05020485 | C2: ='PG MONTHLY DATA'!H2 -> -0.01 | D2: ='PG MONTHLY DATA'!I2 -> 0.39 | E2: ='PG MONTHLY DATA'!J2 -> 0.0039 | F2: ='PG MONTHLY DATA'!V2 -> -0.99 | G2: =F2/100 -> -0.0099 | H2: ='PG MONTHLY DATA'!W2 -> 0.86 | I2: =H2/100 -> 0.0086
A3: ='PG MONTHLY DATA'!A3 -> 45565 | B3: ='PG MONTHLY DATA'!K3 -> 0.0056770433 | C3: ='PG MONTHLY DATA'!H3 -> 0.0172 | D3: ='PG MONTHLY DATA'!I3 -> 0.4 | E3: ='PG MONTHLY DATA'!J3 -> 0.004 | F3: ='PG MONTHLY DATA'!V3 -> -0.13 | G3: =F3/100 -> -0.0013 | H3: ='PG MONTHLY DATA'!W3 -> -2.76 | I3: =H3/100 -> -0.0276 | K3: rMkt,SMB = | L3: =CORREL(C2:C145,G2:G145) -> 0.28334068
A4: ='PG MONTHLY DATA'!A4 -> 45535 | B4: ='PG MONTHLY DATA'!K4 -> 0.062256482 | C4: ='PG MONTHLY DATA'!H4 -> 0.016 | D4: ='PG MONTHLY DATA'!I4 -> 0.48 | E4: ='PG MONTHLY DATA'!J4 -> 0.0048 | F4: ='PG MONTHLY DATA'!V4 -> -3.49 | G4: =F4/100 -> -0.0349 | H4: ='PG MONTHLY DATA'!W4 -> -1.1 | I4: =H4/100 -> -0.011 | K4: rMkt,HML = | L4: =CORREL(C2:C145,I2:I145) -> 0.034419319
A5: ='PG MONTHLY DATA'!A5 -> 45504 | B5: ='PG MONTHLY DATA'!K5 -> -0.029724351 | C5: ='PG MONTHLY DATA'!H5 -> 0.0122 | D5: ='PG MONTHLY DATA'!I5 -> 0.45 | E5: ='PG MONTHLY DATA'!J5 -> 0.0045 | F5: ='PG MONTHLY DATA'!V5 -> 6.81 | G5: =F5/100 -> 0.0681 | H5: ='PG MONTHLY DATA'!W5 -> 5.62 | I5: =H5/100 -> 0.0562 | K5: rSMB,HML = | L5: =CORREL(G2:G145,I2:I145) -> 0.097451031
A6: ='PG MONTHLY DATA'!A6 -> 45473 | B6: ='PG MONTHLY DATA'!K6 -> -0.0017905312 | C6: ='PG MONTHLY DATA'!H6 -> 0.028 | D6: ='PG MONTHLY DATA'!I6 -> 0.41 | E6: ='PG MONTHLY DATA'!J6 -> 0.0041 | F6: ='PG MONTHLY DATA'!V6 -> -3 | G6: =F6/100 -> -0.03 | H6: ='PG MONTHLY DATA'!W6 -> -3.36 | I6: =H6/100 -> -0.0336 | K6: All correlations < 0.5 → LOW collinearity. Factors are largely independent.
A7: ='PG MONTHLY DATA'!A7 -> 45443 | B7: ='PG MONTHLY DATA'!K7 -> 0.0038107843 | C7: ='PG MONTHLY DATA'!H7 -> 0.0433 | D7: ='PG MONTHLY DATA'!I7 -> 0.44 | E7: ='PG MONTHLY DATA'!J7 -> 0.0044 | F7: ='PG MONTHLY DATA'!V7 -> 0.55 | G7: =F7/100 -> 0.0055 | H7: ='PG MONTHLY DATA'!W7 -> -1.31 | I7: =H7/100 -> -0.0131
A8: ='PG MONTHLY DATA'!A8 -> 45412 | B8: ='PG MONTHLY DATA'!K8 -> 0.0011551618 | C8: ='PG MONTHLY DATA'!H8 -> -0.0465 | D8: ='PG MONTHLY DATA'!I8 -> 0.47 | E8: ='PG MONTHLY DATA'!J8 -> 0.0047 | F8: ='PG MONTHLY DATA'!V8 -> -2.37 | G8: =F8/100 -> -0.0237 | H8: ='PG MONTHLY DATA'!W8 -> -0.45 | I8: =H8/100 -> -0.0045 | K8: (8b) FF 3-Factor Coefficients:
A9: ='PG MONTHLY DATA'!A9 -> 45382 | B9: ='PG MONTHLY DATA'!K9 -> 0.016525469 | C9: ='PG MONTHLY DATA'!H9 -> 0.0284 | D9: ='PG MONTHLY DATA'!I9 -> 0.43 | E9: ='PG MONTHLY DATA'!J9 -> 0.0043 | F9: ='PG MONTHLY DATA'!V9 -> -2.5 | G9: =F9/100 -> -0.025 | H9: ='PG MONTHLY DATA'!W9 -> 4.16 | I9: =H9/100 -> 0.0416 | K9: α = | L9: ='FF3 Regression Output'!B16 -> -0.00022048177 | M9: Not significant (see Q9)
A10: ='PG MONTHLY DATA'!A10 -> 45351 | B10: ='PG MONTHLY DATA'!K10 -> 0.0072547537 | C10: ='PG MONTHLY DATA'!H10 -> 0.0507 | D10: ='PG MONTHLY DATA'!I10 -> 0.42 | E10: ='PG MONTHLY DATA'!J10 -> 0.0042 | F10: ='PG MONTHLY DATA'!V10 -> -0.24 | G10: =F10/100 -> -0.0024 | H10: ='PG MONTHLY DATA'!W10 -> -3.43 | I10: =H10/100 -> -0.0343 | K10: β_MKT = | L10: ='FF3 Regression Output'!B17 -> 0.49479135 | M10: Positive, <1 → defensive stock, moves with market but less aggressively
A11: ='PG MONTHLY DATA'!A11 -> 45322 | B11: ='PG MONTHLY DATA'!K11 -> 0.067635199 | C11: ='PG MONTHLY DATA'!H11 -> 0.0073 | D11: ='PG MONTHLY DATA'!I11 -> 0.47 | E11: ='PG MONTHLY DATA'!J11 -> 0.0047 | F11: ='PG MONTHLY DATA'!V11 -> -5.07 | G11: =F11/100 -> -0.0507 | H11: ='PG MONTHLY DATA'!W11 -> -2.38 | I11: =H11/100 -> -0.0238 | K11: β_SMB = | L11: ='FF3 Regression Output'!B18 -> -0.68087139 | M11: Strongly negative → PG behaves as a large-cap stock (expected for P&G)
A12: ='PG MONTHLY DATA'!A12 -> 45291 | B12: ='PG MONTHLY DATA'!K12 -> -0.049766389 | C12: ='PG MONTHLY DATA'!H12 -> 0.0485 | D12: ='PG MONTHLY DATA'!I12 -> 0.43 | E12: ='PG MONTHLY DATA'!J12 -> 0.0043 | F12: ='PG MONTHLY DATA'!V12 -> 6.3 | G12: =F12/100 -> 0.063 | H12: ='PG MONTHLY DATA'!W12 -> 4.89 | I12: =H12/100 -> 0.0489 | K12: β_HML = | L12: ='FF3 Regression Output'!B19 -> 0.067553288 | M12: Small, not significant → minimal value/growth tilt
A13: ='PG MONTHLY DATA'!A13 -> 45260 | B13: ='PG MONTHLY DATA'!K13 -> 0.018862014 | C13: ='PG MONTHLY DATA'!H13 -> 0.0888 | D13: ='PG MONTHLY DATA'!I13 -> 0.44 | E13: ='PG MONTHLY DATA'!J13 -> 0.0044 | F13: ='PG MONTHLY DATA'!V13 -> -0.1 | G13: =F13/100 -> -0.001 | H13: ='PG MONTHLY DATA'!W13 -> 1.67 | I13: =H13/100 -> 0.0167
A14: ='PG MONTHLY DATA'!A14 -> 45230 | B14: ='PG MONTHLY DATA'!K14 -> 0.023889058 | C14: ='PG MONTHLY DATA'!H14 -> -0.0315 | D14: ='PG MONTHLY DATA'!I14 -> 0.47 | E14: ='PG MONTHLY DATA'!J14 -> 0.0047 | F14: ='PG MONTHLY DATA'!V14 -> -3.86 | G14: =F14/100 -> -0.0386 | H14: ='PG MONTHLY DATA'!W14 -> 0.2 | I14: =H14/100 -> 0.002 | K14: (9) H₀: α≤0 vs H₁: α>0 (5% one-tailed)
A15: ='PG MONTHLY DATA'!A15 -> 45199 | B15: ='PG MONTHLY DATA'!K15 -> -0.059243631 | C15: ='PG MONTHLY DATA'!H15 -> -0.0523 | D15: ='PG MONTHLY DATA'!I15 -> 0.43 | E15: ='PG MONTHLY DATA'!J15 -> 0.0043 | F15: ='PG MONTHLY DATA'!V15 -> -2.51 | G15: =F15/100 -> -0.0251 | H15: ='PG MONTHLY DATA'!W15 -> 1.49 | I15: =H15/100 -> 0.0149 | K15: α = | L15: ='FF3 Regression Output'!B16 -> -0.00022048177
A16: ='PG MONTHLY DATA'!A16 -> 45169 | B16: ='PG MONTHLY DATA'!K16 -> -0.017039987 | C16: ='PG MONTHLY DATA'!H16 -> -0.0236 | D16: ='PG MONTHLY DATA'!I16 -> 0.45 | E16: ='PG MONTHLY DATA'!J16 -> 0.0045 | F16: ='PG MONTHLY DATA'!V16 -> -3.14 | G16: =F16/100 -> -0.0314 | H16: ='PG MONTHLY DATA'!W16 -> -1.15 | I16: =H16/100 -> -0.0115 | K16: se(α) = | L16: ='FF3 Regression Output'!C16 -> 0.0032835041
A17: ='PG MONTHLY DATA'!A17 -> 45138 | B17: ='PG MONTHLY DATA'!K17 -> 0.025551404 | C17: ='PG MONTHLY DATA'!H17 -> 0.0321 | D17: ='PG MONTHLY DATA'!I17 -> 0.45 | E17: ='PG MONTHLY DATA'!J17 -> 0.0045 | F17: ='PG MONTHLY DATA'!V17 -> 2.05 | G17: =F17/100 -> 0.0205 | H17: ='PG MONTHLY DATA'!W17 -> 4.06 | I17: =H17/100 -> 0.0406 | K17: t-stat = α/se = | L17: ='FF3 Regression Output'!D16 -> -0.067148317 | M17: t-critical (5%, 1-tail) = | N17: =_xlfn.T.INV(0.95,140) -> 1.6558105
A18: ='PG MONTHLY DATA'!A18 -> 45107 | B18: ='PG MONTHLY DATA'!K18 -> 0.060842105 | C18: ='PG MONTHLY DATA'!H18 -> 0.0646 | D18: ='PG MONTHLY DATA'!I18 -> 0.4 | E18: ='PG MONTHLY DATA'!J18 -> 0.004 | F18: ='PG MONTHLY DATA'!V18 -> 1.49 | G18: =F18/100 -> 0.0149 | H18: ='PG MONTHLY DATA'!W18 -> -0.13 | I18: =H18/100 -> -0.0013 | K18: t-stat < t-critical → FAIL TO REJECT H₀
A19: ='PG MONTHLY DATA'!A19 -> 45077 | B19: ='PG MONTHLY DATA'!K19 -> -0.092358153 | C19: ='PG MONTHLY DATA'!H19 -> 0.0034 | D19: ='PG MONTHLY DATA'!I19 -> 0.36 | E19: ='PG MONTHLY DATA'!J19 -> 0.0036 | F19: ='PG MONTHLY DATA'!V19 -> 1.6 | G19: =F19/100 -> 0.016 | H19: ='PG MONTHLY DATA'!W19 -> -7.79 | I19: =H19/100 -> -0.0779 | K19: No evidence of significantly positive risk-adjusted returns. Alpha ≈ 0.
A20: ='PG MONTHLY DATA'!A20 -> 45046 | B20: ='PG MONTHLY DATA'!K20 -> 0.04821834 | C20: ='PG MONTHLY DATA'!H20 -> 0.0062 | D20: ='PG MONTHLY DATA'!I20 -> 0.35 | E20: ='PG MONTHLY DATA'!J20 -> 0.0035 | F20: ='PG MONTHLY DATA'!V20 -> -3.37 | G20: =F20/100 -> -0.0337 | H20: ='PG MONTHLY DATA'!W20 -> -0.12 | I20: =H20/100 -> -0.0012
A21: ='PG MONTHLY DATA'!A21 -> 45016 | B21: ='PG MONTHLY DATA'!K21 -> 0.077310148 | C21: ='PG MONTHLY DATA'!H21 -> 0.0248 | D21: ='PG MONTHLY DATA'!I21 -> 0.36 | E21: ='PG MONTHLY DATA'!J21 -> 0.0036 | F21: ='PG MONTHLY DATA'!V21 -> -5.48 | G21: =F21/100 -> -0.0548 | H21: ='PG MONTHLY DATA'!W21 -> -9.05 | I21: =H21/100 -> -0.0905 | K21: (10) Significance of MKT, SMB, HML at 1% (two-tailed)
A22: ='PG MONTHLY DATA'!A22 -> 44985 | B22: ='PG MONTHLY DATA'!K22 -> -0.037253069 | C22: ='PG MONTHLY DATA'!H22 -> -0.0257 | D22: ='PG MONTHLY DATA'!I22 -> 0.34 | E22: ='PG MONTHLY DATA'!J22 -> 0.0034 | F22: ='PG MONTHLY DATA'!V22 -> 1.05 | G22: =F22/100 -> 0.0105 | H22: ='PG MONTHLY DATA'!W22 -> -0.8 | I22: =H22/100 -> -0.008 | K22: t-critical (1%, 2-tail) = | L22: =_xlfn.T.INV.2T(0.01,140) -> 2.6114027
A23: ='PG MONTHLY DATA'!A23 -> 44957 | B23: ='PG MONTHLY DATA'!K23 -> -0.064070071 | C23: ='PG MONTHLY DATA'!H23 -> 0.0661 | D23: ='PG MONTHLY DATA'!I23 -> 0.35 | E23: ='PG MONTHLY DATA'!J23 -> 0.0035 | F23: ='PG MONTHLY DATA'!V23 -> 5.01 | G23: =F23/100 -> 0.0501 | H23: ='PG MONTHLY DATA'!W23 -> -3.94 | I23: =H23/100 -> -0.0394 | K23: β_MKT t-stat = | L23: ='FF3 Regression Output'!D17 -> 6.4236032 | M23: p-value = | N23: ='FF3 Regression Output'!E17 -> 1.9365269e-09 | O23: → SIGNIFICANT at 1%
A24: ='PG MONTHLY DATA'!A24 -> 44926 | B24: ='PG MONTHLY DATA'!K24 -> 0.012790105 | C24: ='PG MONTHLY DATA'!H24 -> -0.0638 | D24: ='PG MONTHLY DATA'!I24 -> 0.33 | E24: ='PG MONTHLY DATA'!J24 -> 0.0033 | F24: ='PG MONTHLY DATA'!V24 -> -0.76 | G24: =F24/100 -> -0.0076 | H24: ='PG MONTHLY DATA'!W24 -> 1.34 | I24: =H24/100 -> 0.0134 | K24: β_SMB t-stat = | L24: ='FF3 Regression Output'!D18 -> -5.4810296 | M24: p-value = | N24: ='FF3 Regression Output'!E18 -> 1.9113885e-07 | O24: → SIGNIFICANT at 1%
A25: ='PG MONTHLY DATA'!A25 -> 44895 | B25: ='PG MONTHLY DATA'!K25 -> 0.10469635 | C25: ='PG MONTHLY DATA'!H25 -> 0.0465 | D25: ='PG MONTHLY DATA'!I25 -> 0.29 | E25: ='PG MONTHLY DATA'!J25 -> 0.0029 | F25: ='PG MONTHLY DATA'!V25 -> -3.57 | G25: =F25/100 -> -0.0357 | H25: ='PG MONTHLY DATA'!W25 -> 1.48 | I25: =H25/100 -> 0.0148 | K25: β_HML t-stat = | L25: ='FF3 Regression Output'!D19 -> 0.74869744 | M25: p-value = | N25: ='FF3 Regression Output'!E19 -> 0.45529559 | O25: → NOT significant at 1%
A26: ='PG MONTHLY DATA'!A26 -> 44865 | B26: ='PG MONTHLY DATA'!K26 -> 0.064393069 | C26: ='PG MONTHLY DATA'!H26 -> 0.0785 | D26: ='PG MONTHLY DATA'!I26 -> 0.23 | E26: ='PG MONTHLY DATA'!J26 -> 0.0023 | F26: ='PG MONTHLY DATA'!V26 -> 0.01 | G26: =F26/100 -> 0.0001 | H26: ='PG MONTHLY DATA'!W26 -> 7.97 | I26: =H26/100 -> 0.0797
A27: ='PG MONTHLY DATA'!A27 -> 44834 | B27: ='PG MONTHLY DATA'!K27 -> -0.086646991 | C27: ='PG MONTHLY DATA'!H27 -> -0.0934 | D27: ='PG MONTHLY DATA'!I27 -> 0.19 | E27: ='PG MONTHLY DATA'!J27 -> 0.0019 | F27: ='PG MONTHLY DATA'!V27 -> -0.76 | G27: =F27/100 -> -0.0076 | H27: ='PG MONTHLY DATA'!W27 -> 0.03 | I27: =H27/100 -> 0.0003
A28: ='PG MONTHLY DATA'!A28 -> 44804 | B28: ='PG MONTHLY DATA'!K28 -> -0.0088829386 | C28: ='PG MONTHLY DATA'!H28 -> -0.0377 | D28: ='PG MONTHLY DATA'!I28 -> 0.19 | E28: ='PG MONTHLY DATA'!J28 -> 0.0019 | F28: ='PG MONTHLY DATA'!V28 -> 1.41 | G28: =F28/100 -> 0.0141 | H28: ='PG MONTHLY DATA'!W28 -> 0.18 | I28: =H28/100 -> 0.0018
A29: ='PG MONTHLY DATA'!A29 -> 44773 | B29: ='PG MONTHLY DATA'!K29 -> -0.034738382 | C29: ='PG MONTHLY DATA'!H29 -> 0.0957 | D29: ='PG MONTHLY DATA'!I29 -> 0.08 | E29: ='PG MONTHLY DATA'!J29 -> 0.0008 | F29: ='PG MONTHLY DATA'!V29 -> 2.84 | G29: =F29/100 -> 0.0284 | H29: ='PG MONTHLY DATA'!W29 -> -4.15 | I29: =H29/100 -> -0.0415
A30: ='PG MONTHLY DATA'!A30 -> 44742 | B30: ='PG MONTHLY DATA'!K30 -> -0.02825756 | C30: ='PG MONTHLY DATA'!H30 -> -0.084 | D30: ='PG MONTHLY DATA'!I30 -> 0.06 | E30: ='PG MONTHLY DATA'!J30 -> 0.0006 | F30: ='PG MONTHLY DATA'!V30 -> 2.07 | G30: =F30/100 -> 0.0207 | H30: ='PG MONTHLY DATA'!W30 -> -6 | I30: =H30/100 -> -0.06
A31: ='PG MONTHLY DATA'!A31 -> 44712 | B31: ='PG MONTHLY DATA'!K31 -> -0.079216225 | C31: ='PG MONTHLY DATA'!H31 -> -0.0034 | D31: ='PG MONTHLY DATA'!I31 -> 0.03 | E31: ='PG MONTHLY DATA'!J31 -> 0.0003 | F31: ='PG MONTHLY DATA'!V31 -> -1.84 | G31: =F31/100 -> -0.0184 | H31: ='PG MONTHLY DATA'!W31 -> 8.44 | I31: =H31/100 -> 0.0844
A32: ='PG MONTHLY DATA'!A32 -> 44681 | B32: ='PG MONTHLY DATA'!K32 -> 0.050719895 | C32: ='PG MONTHLY DATA'!H32 -> -0.0941 | D32: ='PG MONTHLY DATA'!I32 -> 0 | E32: ='PG MONTHLY DATA'!J32 -> 0 | F32: ='PG MONTHLY DATA'!V32 -> -1.35 | G32: =F32/100 -> -0.0135 | H32: ='PG MONTHLY DATA'!W32 -> 6.18 | I32: =H32/100 -> 0.0618
A33: ='PG MONTHLY DATA'!A33 -> 44651 | B33: ='PG MONTHLY DATA'!K33 -> -0.019821669 | C33: ='PG MONTHLY DATA'!H33 -> 0.0308 | D33: ='PG MONTHLY DATA'!I33 -> 0 | E33: ='PG MONTHLY DATA'!J33 -> 0 | F33: ='PG MONTHLY DATA'!V33 -> -1.55 | G33: =F33/100 -> -0.0155 | H33: ='PG MONTHLY DATA'!W33 -> -1.9 | I33: =H33/100 -> -0.019
A34: ='PG MONTHLY DATA'!A34 -> 44620 | B34: ='PG MONTHLY DATA'!K34 -> -0.028420069 | C34: ='PG MONTHLY DATA'!H34 -> -0.0228 | D34: ='PG MONTHLY DATA'!I34 -> 0 | E34: ='PG MONTHLY DATA'!J34 -> 0 | F34: ='PG MONTHLY DATA'!V34 -> 2.16 | G34: =F34/100 -> 0.0216 | H34: ='PG MONTHLY DATA'!W34 -> 3.06 | I34: =H34/100 -> 0.0306
A35: ='PG MONTHLY DATA'!A35 -> 44592 | B35: ='PG MONTHLY DATA'!K35 -> -0.019134369 | C35: ='PG MONTHLY DATA'!H35 -> -0.0616 | D35: ='PG MONTHLY DATA'!I35 -> 0 | E35: ='PG MONTHLY DATA'!J35 -> 0 | F35: ='PG MONTHLY DATA'!V35 -> -5.93 | G35: =F35/100 -> -0.0593 | H35: ='PG MONTHLY DATA'!W35 -> 12.86 | I35: =H35/100 -> 0.1286
A36: ='PG MONTHLY DATA'!A36 -> 44561 | B36: ='PG MONTHLY DATA'!K36 -> 0.13131513 | C36: ='PG MONTHLY DATA'!H36 -> 0.0323 | D36: ='PG MONTHLY DATA'!I36 -> 0.01 | E36: ='PG MONTHLY DATA'!J36 -> 0.0001 | F36: ='PG MONTHLY DATA'!V36 -> -1.63 | G36: =F36/100 -> -0.0163 | H36: ='PG MONTHLY DATA'!W36 -> 3.25 | I36: =H36/100 -> 0.0325
A37: ='PG MONTHLY DATA'!A37 -> 44530 | B37: ='PG MONTHLY DATA'!K37 -> 0.011119659 | C37: ='PG MONTHLY DATA'!H37 -> -0.0158 | D37: ='PG MONTHLY DATA'!I37 -> 0 | E37: ='PG MONTHLY DATA'!J37 -> 0 | F37: ='PG MONTHLY DATA'!V37 -> -1.31 | G37: =F37/100 -> -0.0131 | H37: ='PG MONTHLY DATA'!W37 -> -0.37 | I37: =H37/100 -> -0.0037
... A145: ='PG MONTHLY DATA'!A145 -> 41243 | B145: ='PG MONTHLY DATA'!K145 -> 0.0084210861 | C145: ='PG MONTHLY DATA'!H145 -> 0.0078 | D145: ='PG MONTHLY DATA'!I145 -> 0.01 | E145: ='PG MONTHLY DATA'!J145 -> 0.0001 | F145: ='PG MONTHLY DATA'!V145 -> 0.6 | G145: =F145/100 -> 0.006 | H145: ='PG MONTHLY DATA'!W145 -> -0.86 | I145: =H145/100 -> -0.0086

Sheet CAPM Regression Output
A1: SUMMARY OUTPUT
A2: Regression Statistics
A3: Multiple R | B3: 0.36405514
A4: R Square | B4: 0.13253615
A5: Adjusted R Square | B5: 0.12642725
A6: Standard Error | B6: 0.041460956
A7: Observations | B7: 144
A9: ANOVA
B10: df | C10: SS | D10: MS | E10: F | F10: Significance F
A11: Regression | B11: 1 | C11: 0.037294941 | D11: 0.037294941 | E11: 21.695581 | F11: 7.2745792e-06
A12: Residual | B12: 142 | C12: 0.24409954 | D12: 0.0017190109
A13: Total | B13: 143 | C13: 0.28139449
B15: Coefficients | C15: Standard Error | D15: t Stat | E15: P-value | F15: Lower 95% | G15: Upper 95% | H15: Lower 95.0% | I15: Upper 95.0%
A16: Intercept | B16: 0.0017670224 | C16: 0.0035682473 | D16: 0.49520737 | E16: 0.62121918 | F16: -0.0052867281 | G16: 0.0088207729 | H16: -0.0052867281 | I16: 0.0088207729
A17: X Variable 1 | B17: 0.37658026 | C17: 0.080848488 | D17: 4.6578516 | E17: 7.2745792e-06 | F17: 0.21675808 | G17: 0.53640244 | H17: 0.21675808 | I17: 0.53640244

Sheet FF3 Regression Output
A1: SUMMARY OUTPUT
A2: Regression Statistics
A3: Multiple R | B3: 0.53483813
A4: R Square | B4: 0.28605183
A5: Adjusted R Square | B5: 0.27075294
A6: Standard Error | B6: 0.037881495
A7: Observations | B7: 144
A9: ANOVA
B10: df | C10: SS | D10: MS | E10: F | F10: Significance F
A11: Regression | B11: 3 | C11: 0.080493407 | D11: 0.026831136 | E11: 18.697555 | F11: 2.9488534e-10
A12: Residual | B12: 140 | C12: 0.20090108 | D12: 0.0014350077
A13: Total | B13: 143 | C13: 0.28139449
B15: Coefficients | C15: Standard Error | D15: t Stat | E15: P-value | F15: Lower 95% | G15: Upper 95% | H15: Lower 95.0% | I15: Upper 95.0%
A16: Intercept | B16: -0.00022048177 | C16: 0.0032835041 | D16: -0.067148317 | E16: 0.94655943 | F16: -0.0067121458 | G16: 0.0062711822 | H16: -0.0067121458 | I16: 0.0062711822
A17: X Variable 1 (MKT-RF) | B17: 0.49479135 | C17: 0.077027073 | D17: 6.4236032 | E17: 1.9365269e-09 | F17: 0.34250469 | G17: 0.64707802 | H17: 0.34250469 | I17: 0.64707802
A18: X Variable 2 (SMB) | B18: -0.68087139 | C18: 0.12422327 | D18: -5.4810296 | E18: 1.9113885e-07 | F18: -0.92646746 | G18: -0.43527532 | H18: -0.92646746 | I18: -0.43527532
A19: X Variable 3 (HML) | B19: 0.067553288 | C19: 0.090227753 | D19: 0.74869744 | E19: 0.45529559 | F19: -0.11083183 | G19: 0.2459384 | H19: -0.11083183 | I19: 0.2459384
